---
title: "错误处理技巧"
date: 2023-10-07T22:03:53+08:00
---

## 拦截错误

### try/catch 语句

一般来说，JavaScript 中会以 try/catch 来拦截错误，且常常会搭配 finally 来减少重复的程序代码：

```js
try {
  // 可能出错的程序代码
} catch (error) {
  // 处理错误
} finally {
  // 此处必定执行
}
```

需要注意的是，在 **finally** 内使用 return 或 throw 会**覆写**掉 try/catch 内原本的操作：

```js
function foo() {
  try {
    throw new Error("Hello World!");
  } catch (error) {
    throw error;
  } finally {
    return "finally";
  }
}
console.log(foo()); // finally
```

```js
function bar() {
  try {
    return "try";
  } finally {
    throw new Error("finally");
  }
}
console.log(bar()); // Uncaught Error: finally
```

### 异步错误拦截

try/catch 只能拦截同步的错误，例如：

```js
try {
  Promise.reject("Promise rejection");
  setTimeout(() => {
    throw new Error("Timeout error");
  });
} catch (error) {
  console.error("err", error); // 没有拦截到错误
}
```

若要拦截错误，则需要加入额外的程序代码，例如：

```js
Promise.reject("Promise rejection")
  .then((data) => console.log("OK"))
  .catch((reason) => {
    console.log("Rejection handled.");
  })
  .finally(() => {
    console.log("Finally");
  });

setTimeout(() => {
  try {
    throw new Error("Timeout error");
  } catch (error) {
    console.log("Error handled.");
  }
});
```

此外，将 Callback 语句转化为 Promise 也是常见的用法，这么做的好处是可以把错误从 Callback 中取出来：

```js
const promise = new Promise((resolve, reject) => {
  setTimeout(() => {
    try {
      throw new Error("Timeout error!");
    } catch (error) {
      reject(error);
    }
  });
});
promise.catch((error) => {
  handleError(error); // 处理错误
});
```

### 错误拦截时机

try/catch 应该用于无法控制的错误，例如：

- 无法避免的错误：如 JSON.parse，执行函数时无法保证是否会出错，需要使用 try/catch 来处理错误，确保程序代码不会中断执行。

- 定制化错误：使用第三方软件包时，可能出现软件包自定义的错误提示信息，或者非预期的错误，由于无法改变软件包的行为，可以使用 try/catch 拦截错误，再定制错误提示信息或处理错误。

1. 避免不必要的拦截

如果明确知道程序代码在哪些情况会出错，就不应该使用 try/catch，请看以下范例：

- 知道当变量 str 不是字符串类型时会出错，应做好事前检查，主动解释并抛出错误。

```js
// 做好事前检查，主动解释并抛出错误
if (typeof str !== "string") {
  throw new Error("str must be a string.");
}
return str.toLowerCase();
```

- 知道此段程序代码可能会出错，因此使用 try/catch 来拦截错误，然而这么做并没有什么帮助。

```js
// 没有意义的 try/catch
try {
  return str.toLowerCase();
} catch (error) {
  throw error;
}
```

2. 避免过早拦截

只有在知道该如何处理错误时，才能够拦截错误。

如下：在 say 函数中，以 try/catch 程序块中包含 logOrError 函数来拦截可能会出现的错误，虽然可以在出错时避免程序中断，但 say 作为一个底层共享函数，无法得知网页应用的逻辑以及用户当前的应用场景，也无法正确处理错误，此外，如果拦截了错误，却不进行处理，对外层函数而言就如同没有发生错误，通常会提升 Debug 的难度：

```js
function logOrError(message) {
  if (Math.random() < 0.5) {
    throw new Error(message);
  }
  console.log(message);
}
function say(message) {
  try {
    logOrError(message);
  } catch (error) {
    console.error("Something went wrong."); // 过早拦截错误且打印出无用的信息
  }
}
function sayHi() {
  try {
    say("hi");
  } catch (error) {
    console.error("Failed to say hi. Please try again."); // 较轻微的错误
  }
}
function mustSayHi() {
  try {
    say("hi");
  } catch (error) {
    console.error("Fatal error!"); // 遭遇重大错误，必须重新刷新页面
    window.location.reload();
  }
}
```

想要避免上述问题，可以删除 try/catch 语句，交由其他函数（如 sayHi、mustSayHi）来处理错误：

```js
function say(message) {
  logOrError(message);
}
```

或者在 say 函数中进行基本的错误处理，再抛出错误：

```js
function say(message) {
  try {
    logOrError(message);
  } catch (error) {
    console.error(error); // 必要时可以先行处理错误
    throw new Error(`say(): Failed to log ${message}.`); // 更详细的错误提示信息
  }
}
```

### 错误事件

即使尽可能做好错误处理，还是有可能出现没有拦截到的错误。

没有被拦截到的错误会在 window 上触发 error 或 `unhandledrejection(Promise)` 事件。

拦截错误事件可以视为包了一层全局的 try/catch 语句，不过一般而言，若有正确的错误处理方式，则不应该出现该事件：

```js
function handleUncaughtError(event) {
  console.log(event);
  event.preventDefault(); // 避免默认操作，如打印出错误提示信息
}
window.addEventListener("error", handleUncaughtError);
window.addEventListener("unhandledrejection", handleUncaughtError);
```

## 抛出错误

只要程序代码出现无法正确执行的情况，就应该使用 throw 语句来主动抛出错误

通过自定义错误类别可以协助区分错误类型，并根据不同类型进行不同的错误处理，

如下，利用 TrustedError 表示已知错误，并用 ApiError 表示 API 相关错误：

```js
class TrustedError extends Error {
  constructor(message) {
    super(message);
    this.name = new.target.name;
  }
}
class ApiError extends TrustedError {
  constructor(message, status) {
    super(message);
    this.status = status;
  }
}
```

遇到 API 错误时，抛出自定义的错误（如 ApiError），在拦截时能根据错误类别进行相应的处理：

```js
try {
  throw new ApiError("Path not found.", 404);
} catch (error) {
  if (error instanceof ApiError) {
    console.log(`${error.name}: ${error.message}. (Status ${error.status})`);
    // ApiError: Path not found. (Status 404)
  } else if (error instanceof TrustedError) {
    console.log(error.message);
  } else {
    handleUnexpectedError(error); // 处理非预期的错误
  }
}
```
